2021/01/26 20:10:33 Attempt 1 of http call to http://10.0.0.4:16384/sendlogstoartifacts/info
2021/01/26 20:10:33 Http request failed with status: 500
Response body: Unable to write to log.


2021/01/26 20:10:33 Response code 500, retrying after 1 seconds
2021/01/26 20:10:34 Attempt 2 of http call to http://10.0.0.4:16384/sendlogstoartifacts/info
2021/01/26 20:10:34 Http request failed with status: 500
Response body: Unable to write to log.


2021/01/26 20:10:34 Response code 500, retrying after 2 seconds
[2021-01-26T20:10:35.170808] Entering context manager injector.
[context_manager_injector.py] Command line Options: Namespace(inject=['ProjectPythonPath:context_managers.ProjectPythonPath', 'RunHistory:context_managers.RunHistory', 'TrackUserError:context_managers.TrackUserError'], invocation=['train.py', '--C', '1', '--max_iter', '100'])
2021/01/26 20:10:36 Attempt 3 of http call to http://10.0.0.4:16384/sendlogstoartifacts/info
Script type = None
Starting the daemon thread to refresh tokens in background for process with pid = 94
2021/01/26 20:10:36 Attempt 1 of http call to http://10.0.0.4:16384/sendlogstoartifacts/status
Entering Run History Context Manager.
[2021-01-26T20:10:37.929260] Current directory: /mnt/batch/tasks/shared/LS_root/jobs/quick-starts-ws-136159/azureml/hd_5fa334d0-7ec2-4ac3-a262-1e187594feb0_11/mounts/workspaceblobstore/azureml/HD_5fa334d0-7ec2-4ac3-a262-1e187594feb0_11
[2021-01-26T20:10:37.930410] Preparing to call script [train.py] with arguments:['--C', '1', '--max_iter', '100']
[2021-01-26T20:10:37.931428] After variable expansion, calling script [train.py] with arguments:['--C', '1', '--max_iter', '100']

2021-01-26 20:10:38.673071 | ActivityCompleted: Activity=from_delimited_files, HowEnded=Failure, Duration=6962.79 [ms], Info = {'activity_id': '17f25005-d6ef-440e-bb8c-8ad5391da8b6', 'activity_name': 'from_delimited_files', 'activity_type': 'PublicApi', 'app_name': 'TabularDataset', 'source': 'azureml.dataset', 'version': '1.21.0.post1', 'dataprepVersion': '2.8.2', 'subscription': '610d6e37-4747-4a20-80eb-3aad70a55f43', 'run_id': 'HD_5fa334d0-7ec2-4ac3-a262-1e187594feb0_11', 'resource_group': 'aml-quickstarts-136159', 'workspace_name': 'quick-starts-ws-136159', 'experiment_id': '87ac462b-3d7c-4a28-b40f-20261bf35fc2', 'location': 'southcentralus'}, Exception=DatasetValidationError; DatasetValidationError:
	Message: Cannot load any data from the specified path. Make sure the path is accessible and contains data.
The Dataflow produced no records.| session_id=l_f9dab1be-424a-47ed-ad9e-2545026b3ed9
	InnerException None
	ErrorResponse 
{
    "error": {
        "code": "UserError",
        "message": "Cannot load any data from the specified path. Make sure the path is accessible and contains data.\nThe Dataflow produced no records.| session_id=l_f9dab1be-424a-47ed-ad9e-2545026b3ed9"
    }
}
Starting the daemon thread to refresh tokens in background for process with pid = 94


[2021-01-26T20:10:45.761761] The experiment failed. Finalizing run...
Cleaning up all outstanding Run operations, waiting 900.0 seconds
1 items cleaning up...
Cleanup took 0.08073687553405762 seconds
Starting the daemon thread to refresh tokens in background for process with pid = 94
Traceback (most recent call last):
  File "/azureml-envs/azureml_ba9520bf386d662001eeb9523395794e/lib/python3.6/site-packages/azureml/data/dataset_error_handling.py", line 65, in _validate_has_data
    dataflow.verify_has_data()
  File "/azureml-envs/azureml_ba9520bf386d662001eeb9523395794e/lib/python3.6/site-packages/azureml/dataprep/api/_loggerfactory.py", line 206, in wrapper
    return func(*args, **kwargs)
  File "/azureml-envs/azureml_ba9520bf386d662001eeb9523395794e/lib/python3.6/site-packages/azureml/dataprep/api/dataflow.py", line 876, in verify_has_data
    raise DataflowValidationError("The Dataflow produced no records.")
azureml.dataprep.api.dataflow.DataflowValidationError: 
Error Code: Empty
Error Message: The Dataflow produced no records.| session_id=l_f9dab1be-424a-47ed-ad9e-2545026b3ed9

During handling of the above exception, another exception occurred:

Traceback (most recent call last):
  File "/mnt/batch/tasks/shared/LS_root/jobs/quick-starts-ws-136159/azureml/hd_5fa334d0-7ec2-4ac3-a262-1e187594feb0_11/mounts/workspaceblobstore/azureml/HD_5fa334d0-7ec2-4ac3-a262-1e187594feb0_11/azureml-setup/context_manager_injector.py", line 210, in execute_with_context
    runpy.run_path(sys.argv[0], globals(), run_name="__main__")
  File "/azureml-envs/azureml_ba9520bf386d662001eeb9523395794e/lib/python3.6/runpy.py", line 263, in run_path
    pkg_name=pkg_name, script_name=fname)
  File "/azureml-envs/azureml_ba9520bf386d662001eeb9523395794e/lib/python3.6/runpy.py", line 96, in _run_module_code
    mod_name, mod_spec, pkg_name, script_name)
  File "/azureml-envs/azureml_ba9520bf386d662001eeb9523395794e/lib/python3.6/runpy.py", line 85, in _run_code
    exec(code, run_globals)
  File "train.py", line 14, in <module>
    ds = TabularDatasetFactory.from_delimited_files(path=data_path)
  File "/azureml-envs/azureml_ba9520bf386d662001eeb9523395794e/lib/python3.6/site-packages/azureml/data/_loggerfactory.py", line 129, in wrapper
    return func(*args, **kwargs)
  File "/azureml-envs/azureml_ba9520bf386d662001eeb9523395794e/lib/python3.6/site-packages/azureml/data/dataset_factory.py", line 324, in from_delimited_files
    validate or infer_column_types or _is_inference_required(set_column_types))
  File "/azureml-envs/azureml_ba9520bf386d662001eeb9523395794e/lib/python3.6/site-packages/azureml/data/dataset_factory.py", line 966, in _transform_and_validate
    _validate_has_data(dataflow, 'Cannot load any data from the specified path. '
  File "/azureml-envs/azureml_ba9520bf386d662001eeb9523395794e/lib/python3.6/site-packages/azureml/data/dataset_error_handling.py", line 68, in _validate_has_data
    raise DatasetValidationError(error_message + '\n' + e.compliant_message, exception=e)
azureml.data.dataset_error_handling.DatasetValidationError: DatasetValidationError:
	Message: Cannot load any data from the specified path. Make sure the path is accessible and contains data.
The Dataflow produced no records.| session_id=l_f9dab1be-424a-47ed-ad9e-2545026b3ed9
	InnerException None
	ErrorResponse 
{
    "error": {
        "code": "UserError",
        "message": "Cannot load any data from the specified path. Make sure the path is accessible and contains data.\nThe Dataflow produced no records.| session_id=l_f9dab1be-424a-47ed-ad9e-2545026b3ed9"
    }
}

During handling of the above exception, another exception occurred:

Traceback (most recent call last):
  File "train.py", line 14, in <module>
    ds = TabularDatasetFactory.from_delimited_files(path=data_path)
  File "/azureml-envs/azureml_ba9520bf386d662001eeb9523395794e/lib/python3.6/site-packages/azureml/data/_loggerfactory.py", line 129, in wrapper
    return func(*args, **kwargs)
  File "/azureml-envs/azureml_ba9520bf386d662001eeb9523395794e/lib/python3.6/site-packages/azureml/data/dataset_factory.py", line 324, in from_delimited_files
    validate or infer_column_types or _is_inference_required(set_column_types))
  File "/azureml-envs/azureml_ba9520bf386d662001eeb9523395794e/lib/python3.6/site-packages/azureml/data/dataset_factory.py", line 966, in _transform_and_validate
    _validate_has_data(dataflow, 'Cannot load any data from the specified path. '
  File "/azureml-envs/azureml_ba9520bf386d662001eeb9523395794e/lib/python3.6/site-packages/azureml/data/dataset_error_handling.py", line 68, in _validate_has_data
    raise DatasetValidationError(error_message + '\n' + e.compliant_message, exception=e)
UserScriptException: UserScriptException:
	Message: Cannot load any data from the specified path. Make sure the path is accessible and contains data.
The Dataflow produced no records.| session_id=l_f9dab1be-424a-47ed-ad9e-2545026b3ed9
	InnerException DatasetValidationError:
	Message: Cannot load any data from the specified path. Make sure the path is accessible and contains data.
The Dataflow produced no records.| session_id=l_f9dab1be-424a-47ed-ad9e-2545026b3ed9
	InnerException None
	ErrorResponse 
{
    "error": {
        "code": "UserError",
        "message": "Cannot load any data from the specified path. Make sure the path is accessible and contains data.\nThe Dataflow produced no records.| session_id=l_f9dab1be-424a-47ed-ad9e-2545026b3ed9"
    }
}
	ErrorResponse 
{
    "error": {
        "code": "UserError",
        "message": "Cannot load any data from the specified path. Make sure the path is accessible and contains data.\nThe Dataflow produced no records.| session_id=l_f9dab1be-424a-47ed-ad9e-2545026b3ed9"
    }
}

[2021-01-26T20:10:46.043161] Finished context manager injector with Exception.
2021/01/26 20:10:49 Failed to parse control script error: /mnt/batch/tasks/workitems/29e5ac5e-e2af-4485-9a83-45e01940460f/job-1/hd_5fa334d0-7ec2-4ac_50299799-4fa2-4a23-9ee6-9e04e7a166b0/wd/runTaskLetTask_error.json to json File /mnt/batch/tasks/workitems/29e5ac5e-e2af-4485-9a83-45e01940460f/job-1/hd_5fa334d0-7ec2-4ac_50299799-4fa2-4a23-9ee6-9e04e7a166b0/wd/runTaskLetTask_error.json doesn't exist
2021/01/26 20:10:49 Failed to run the wrapper cmd with err: exit status 1
2021/01/26 20:10:49 Attempt 1 of http call to http://10.0.0.4:16384/sendlogstoartifacts/status
2021/01/26 20:10:49 mpirun version string: {
Intel(R) MPI Library for Linux* OS, Version 2018 Update 3 Build 20180411 (id: 18329)
Copyright 2003-2018 Intel Corporation.
}
2021/01/26 20:10:49 MPI publisher: intel ; version: 2018
2021/01/26 20:10:49 Process Exiting with Code:  1
